Workbook

Sheet Read Me
A1: Cost and Scaling: AI SaaS Workspace (Project 1)
A3: Currency: USD. Date prices accessed: 2026-10-25. AWS region: us-east-1 (N. Virginia). Hostinger prices are not region-specific.
A4: Sheets: Assumptions (inputs) -> Prices (each price with source URL and date) -> Hosting Comparison (Hostinger vs AWS, 100-user MVP) -> Scaling (100 / 1,000 / 10,000 / 1,000,000 users).
A5: Colour code: blue text = hardcoded input or sourced price; black = formula; green = link to another sheet; yellow fill = ASSUMPTION YOU SHOULD REVIEW or value still missing.
A7: How to read the numbers
A8: 1. Every price is on the Prices sheet with a URL. Several AWS prices were read from third-party mirrors of the AWS price list, because aws.amazon.com pricing pages load dynamically. Open the official URL in the 'Official page to verify' column and correct any price that differs before you submit.
A9: 2. Usage figures (asks per user, tokens per ask, document sizes, traffic peaks) are ASSUMPTIONS, not measurements. Replace them with numbers from your own demo/logs where you can.
A10: 3. Items with no sourced price (monitoring, queue service, domain, Jina reranker, backups on Hostinger) are listed as UNPRICED and excluded from totals. They are not assumed to be free unless a note says self-hosted.
A11: 4. The 1,000,000-user column is an order-of-magnitude estimate built from multiples of priced instances. It is not a design that has been load-tested.

Sheet Assumptions
A1: Assumptions (inputs)
A3: Assumption | B3: Value | C3: Unit | D3: Why this value (change it if you have data)
A4: Hours per month | B4: 730 | C4: hours | D4: Standard cloud billing month (365*24/12).
A5: Monthly active share of registered users | B5: 0.3 | C5: fraction | D5: ASSUMPTION: 3 in 10 registered users ask at least once per month.
A6: Asks per active user per month | B6: 60 | C6: asks | D6: ASSUMPTION: about 2 questions per working day.
A7: Average LLM input tokens per ask | B7: 1000 | C7: tokens | D7: ASSUMPTION: 3 retrieved chunks (about 200 tokens each) + instructions + question.
A8: Average LLM output tokens per ask | B8: 250 | C8: tokens | D8: ASSUMPTION: short grounded answers; code caps output at 800.
A9: Embedding tokens per ask (the question) | B9: 40 | C9: tokens | D9: ASSUMPTION.
A10: Share of asks that reach the LLM | B10: 0.85 | C10: fraction | D10: ASSUMPTION: the rest are 'not found' and skip the LLM.
A11: New documents per active user per month | B11: 2 | C11: docs | D11: ASSUMPTION.
A12: Average tokens per document | B12: 6000 | C12: tokens | D12: ASSUMPTION: about 10-12 pages.
A13: Embedding overhead from chunk overlap | B13: 1.125 | C13: x | D13: Chunk size 800 characters, overlap 100 -> about 1.125x.
A14: Average uploaded file size | B14: 1.5 | C14: MB | D14: ASSUMPTION. Upload limit in code is 20 MB.
A15: Database size per document (chunks + vectors + index) | B15: 0.5 | C15: MB | D15: ASSUMPTION: ~30 chunks x (4 KB vector + 1 KB text) x ~3 for index and overhead.
... A23: Minimum app servers once high availability is needed | B23: 2 | C23: servers | D23: Two servers so one can fail.

Sheet Hosting Comparison
A1: Hosting comparison: 100-user MVP, monthly (USD)
A3: Component | B3: Hostinger VPS option | C3: Qty | D3: Unit price | E3: Monthly | F3: AWS option | G3: Qty | H3: Unit price | I3: Monthly
A4: Compute | B4: KVM 2 plan (includes 2 vCPU, 8 GB RAM) | C4: 1 | D4: =Prices!$E$9 -> 14.99 | E4: =C4*D4 -> 14.99 | F4: EC2 t3.large (app server) | G4: =Scaling!$B$10 -> 1 | H4: =Prices!$E$11*Assumptions!$B$4 -> 60.736 | I4: =G4*H4 -> 60.736
A5: Database | B5: Postgres + pgvector on the same VPS (software is open source) | C5: 0 | D5: 0 | E5: =C5*D5 -> 0 | F5: RDS db.t3.medium Single-AZ | G5: 1 | H5: =Prices!$E$13*Assumptions!$B$4 -> 52.56 | I5: =G5*H5 -> 52.56
A6: Database storage | B6: Included in the 100 GB NVMe disk | C6: 0 | D6: 0 | E6: =C6*D6 -> 0 | F6: RDS gp3 storage (GB) | G6: =Scaling!$B$12 -> 0.390625 | H6: =Prices!$E$15 -> 0.115 | I6: =G6*H6 -> 0.044921875
A7: File/object storage | B7: Local disk on the VPS (included) | C7: 0 | D7: 0 | E7: =C7*D7 -> 0 | F7: S3 Standard (GB) | G7: =Scaling!$B$11 -> 1.171875 | H7: =Prices!$E$17 -> 0.023 | I7: =G7*H7 -> 0.026953125
A8: Backups | B8: UNPRICED: Hostinger backup option not sourced | C8: 0 | D8: 0 | E8: =C8*D8 -> 0 | F8: RDS backup beyond free (GB) | G8: =MAX(0,Scaling!$B$12*(Assumptions!$B$21-1)) -> 0.1953125 | H8: =Prices!$E$16 -> 0.095 | I8: =G8*H8 -> 0.018554688
A9: Bandwidth | B9: 8 TB/month included in plan | C9: 0 | D9: 0 | E9: =C9*D9 -> 0 | F9: Data transfer out above free (GB) | G9: =MAX(0,Scaling!$B$17-Prices!$E$21) -> 0 | H9: =Prices!$E$20 -> 0.09 | I9: =G9*H9 -> 0
A10: Monitoring | B10: UNPRICED (self-hosted open-source tools would run on the same VPS) | C10: 0 | D10: 0 | E10: =C10*D10 -> 0 | F10: UNPRICED: CloudWatch not sourced | G10: 0 | H10: 0 | I10: =G10*H10 -> 0
A11: Queue / background jobs | B11: Thread today; Redis on same VPS if added (no vendor price) | C11: 0 | D11: 0 | E11: =C11*D11 -> 0 | F11: UNPRICED: SQS or ElastiCache not sourced | G11: 0 | H11: 0 | I11: =G11*H11 -> 0
A12: Domain | B12: UNPRICED: registrar price not sourced | C12: 0 | D12: 0 | E12: =C12*D12 -> 0 | F12: UNPRICED: Route 53 not sourced | G12: 0 | H12: 0 | I12: =G12*H12 -> 0
A13: Paid APIs: embeddings | B13: OpenAI text-embedding-3-small | C13: 1 | D13: =Scaling!$B$19 -> 0.00954 | E13: =C13*D13 -> 0.00954 | F13: OpenAI text-embedding-3-small | G13: 1 | H13: =Scaling!$B$19 -> 0.00954 | I13: =G13*H13 -> 0.00954
A14: Paid APIs: LLM (gpt-6-luna) | B14: OpenAI gpt-6-luna | C14: 1 | D14: =Scaling!$B$20 -> 0.34425 | E14: =C14*D14 -> 0.34425 | F14: OpenAI gpt-6-luna | G14: 1 | H14: =Scaling!$B$20 -> 0.34425 | I14: =G14*H14 -> 0.34425
A15: Monthly total (priced items only) | E15: =SUM(E4:E14) -> 15.34379 | I15: =SUM(I4:I14) -> 113.74022
A16: Infrastructure only (excluding the two paid API rows) | E16: =SUM(E4:E12) -> 14.99 | I16: =SUM(I4:I12) -> 113.38643
A18: Reading this: Hostinger bundles compute, storage and bandwidth in one fixed price, so it is far cheaper for an MVP but is one server (no automatic failover) and backups/monitoring are on you. AWS costs more but separates concerns (managed database with backups, object storage, room to scale out). Prices: see Prices sheet for URLs and the date accessed.

Sheet Prices
A1: Prices (vendor, unit price, source URL, date accessed)
A3: Key | B3: Vendor | C3: Item | D3: Unit | E3: Price (USD) | F3: Region | G3: Source type | H3: Source URL used | I3: Official page to verify | J3: Date accessed | K3: Note
A4: luna_in | B4: OpenAI | C4: gpt-6-luna input | D4: per 1M tokens | E4: 0.1 | F4: Global | G4: Vendor page | H4: https://developers.openai.com/api/docs/pricing | I4: https://developers.openai.com/api/docs/pricing | J4: 2026-10-25 | K4: Standard processing, short context.
A5: luna_out | B5: OpenAI | C5: gpt-6-luna output | D5: per 1M tokens | E5: 0.5 | F5: Global | G5: Vendor page | H5: https://developers.openai.com/api/docs/pricing | I5: https://developers.openai.com/api/docs/pricing | J5: 2026-10-25
A6: sol_in | B6: OpenAI | C6: gpt-6.1-sol input | D6: per 1M tokens | E6: 2 | F6: Global | G6: Vendor page | H6: https://developers.openai.com/api/docs/pricing | I6: https://developers.openai.com/api/docs/pricing | J6: 2026-10-25 | K6: Higher-quality tier to compare against.
A7: sol_out | B7: OpenAI | C7: gpt-6.1-sol output | D7: per 1M tokens | E7: 10 | F7: Global | G7: Vendor page | H7: https://developers.openai.com/api/docs/pricing | I7: https://developers.openai.com/api/docs/pricing | J7: 2026-10-25
A8: embed | B8: OpenAI | C8: text-embedding-3-small | D8: per 1M tokens | E8: 0.02 | F8: Global | G8: Third-party mirror | H8: https://www.llmreference.com/model/text-embedding-3-small/openai-api | I8: https://developers.openai.com/api/docs/pricing | J8: 2026-10-25 | K8: Embedding rows were not on the official page when read; VERIFY this price.
A9: kvm2 | B9: Hostinger | C9: VPS KVM 2 (2 vCPU, 8 GB RAM, 100 GB NVMe, 8 TB bandwidth) | D9: per month | E9: 14.99 | F9: n/a (USD) | G9: Vendor page (markdown copy) | H9: https://www.hostinger.com/vps-hosting.md | I9: https://www.hostinger.com/vps-hosting | J9: 2026-10-25 | K9: Renewal price. Promo price on a 24-month term was listed as $8.99. Renewal is used for a realistic budget.
A10: kvm4 | B10: Hostinger | C10: VPS KVM 4 (4 vCPU, 16 GB RAM, 200 GB NVMe, 16 TB bandwidth) | D10: per month | E10: 28.99 | F10: n/a (USD) | G10: Vendor page (markdown copy) | H10: https://www.hostinger.com/vps-hosting.md | I10: https://www.hostinger.com/vps-hosting | J10: 2026-10-25 | K10: Renewal price. Promo price on a 24-month term was listed as $12.99.
A11: t3large | B11: AWS | C11: EC2 t3.large (2 vCPU, 8 GiB) Linux on-demand | D11: per hour | E11: 0.0832 | F11: us-east-1 | G11: Third-party mirror | H11: https://www.doit.com/compute/spot/us-east-1/t3.large | I11: https://aws.amazon.com/ec2/pricing/on-demand/ | J11: 2026-10-25 | K11: Verify on the AWS page or AWS Pricing Calculator.
A12: g5xl | B12: AWS | C12: EC2 g5.xlarge (1x NVIDIA A10G, 16 GiB) Linux on-demand | D12: per hour | E12: 1.006 | F12: us-east-1 | G12: Third-party mirror | H12: https://www.doit.com/compute/spot/us-east-1/g5.xlarge | I12: https://aws.amazon.com/ec2/pricing/on-demand/ | J12: 2026-10-25 | K12: Self-hosted open-source model option.
A13: rds_t3m | B13: AWS | C13: RDS PostgreSQL db.t3.medium (2 vCPU, 4 GiB), Single-AZ | D13: per hour | E13: 0.072 | F13: us-east-1 | G13: Third-party mirror | H13: https://cloudprice.net/aws/rds/instances/db.t3.medium | I13: https://aws.amazon.com/rds/postgresql/pricing/ | J13: 2026-10-25 | K13: pgvector is supported on RDS PostgreSQL; confirm for your engine version.
A14: rds_r6g | B14: AWS | C14: RDS PostgreSQL db.r6g.large (2 vCPU, 16 GiB), Multi-AZ | D14: per hour | E14: 0.45 | F14: us-east-1 | G14: Third-party (case study, checked Aug 2026) | H14: https://selfhost.dev/case-studies/aws-rds-cost-optimization-saas/ | I14: https://aws.amazon.com/rds/postgresql/pricing/ | J14: 2026-10-25 | K14: Multi-AZ rate as quoted in the source.
A15: rds_gp3 | B15: AWS | C15: RDS gp3 storage | D15: per GB-month | E15: 0.115 | F15: us-east-1 | G15: Third-party mirror | H15: https://selfhost.dev/blog/aws-rds-cost-breakdown-2026/ | I15: https://aws.amazon.com/rds/postgresql/pricing/ | J15: 2026-10-25 | K15: Billed on both nodes under Multi-AZ (per source).
A16: rds_bkp | B16: AWS | C16: RDS backup storage beyond free allocation | D16: per GB-month | E16: 0.095 | F16: us-east-1 | G16: Third-party (case study) | H16: https://selfhost.dev/case-studies/aws-rds-cost-optimization-saas/ | I16: https://aws.amazon.com/rds/postgresql/pricing/ | J16: 2026-10-25 | K16: Free up to the size of the database, per the sources read.
A17: s3_gb | B17: AWS | C17: S3 Standard storage (first 50 TB) | D17: per GB-month | E17: 0.023 | F17: us-east-1 | G17: Third-party mirror | H17: https://costgoat.com/pricing/amazon-s3 | I17: https://aws.amazon.com/s3/pricing/ | J17: 2026-10-25
A18: s3_put | B18: AWS | C18: S3 PUT/COPY/POST/LIST requests | D18: per 1,000 | E18: 0.005 | F18: us-east-1 | G18: Third-party mirror | H18: https://costgoat.com/pricing/amazon-s3 | I18: https://aws.amazon.com/s3/pricing/ | J18: 2026-10-25
A19: s3_get | B19: AWS | C19: S3 GET requests | D19: per 1,000 | E19: 0.0004 | F19: us-east-1 | G19: Third-party mirror | H19: https://costgoat.com/pricing/amazon-s3 | I19: https://aws.amazon.com/s3/pricing/ | J19: 2026-10-25
A20: egress | B20: AWS | C20: Data transfer out to internet (first 10 TB tier) | D20: per GB | E20: 0.09 | F20: us-east-1 | G20: Third-party mirror | H20: https://costgoat.com/pricing/amazon-s3 | I20: https://aws.amazon.com/s3/pricing/ | J20: 2026-10-25
A21: egress_free | B21: AWS | C21: Free data transfer out per month (all services) | D21: GB | E21: 100 | F21: us-east-1 | G21: Third-party mirror | H21: https://costgoat.com/pricing/amazon-s3 | I21: https://aws.amazon.com/s3/pricing/ | J21: 2026-10-25
A23: UNPRICED items (no sourced price; excluded from totals):
A24: Jina reranker API (optional; look up at jina.ai pricing)
A25: AWS CloudWatch / monitoring
A26: Managed queue (SQS) or Redis
A27: Domain name and DNS
A28: Hostinger backup add-on
A29: Application load balancer, NAT gateway, public IPv4 charges (AWS)

Sheet Scaling
A1: Scaling scenarios (monthly, USD)
A3: Line | B3: 100 users | C3: 1,000 users | D3: 10,000 users | E3: 1,000,000 users | F3: How calculated
A4: Registered users | B4: 100 | C4: 1000 | D4: 10000 | E4: 1000000 | F4: Scenario input
A5: Monthly active users | B5: =B4*Assumptions!$B$5 -> 30 | C5: =C4*Assumptions!$B$5 -> 300 | D5: =D4*Assumptions!$B$5 -> 3000 | E5: =E4*Assumptions!$B$5 -> 300000 | F5: registered x active share
A6: Asks per month | B6: =B5*Assumptions!$B$6 -> 1800 | C6: =C5*Assumptions!$B$6 -> 18000 | D6: =D5*Assumptions!$B$6 -> 180000 | E6: =E5*Assumptions!$B$6 -> 18000000 | F6: MAU x asks per active user
A7: Average asks per second | B7: =B6/(30*24*3600) -> 0.00069444444 | C7: =C6/(30*24*3600) -> 0.0069444444 | D7: =D6/(30*24*3600) -> 0.069444444 | E7: =E6/(30*24*3600) -> 6.9444444 | F7: asks / seconds in 30 days
A8: Peak asks per second | B8: =B7*Assumptions!$B$18 -> 0.0069444444 | C8: =C7*Assumptions!$B$18 -> 0.069444444 | D8: =D7*Assumptions!$B$18 -> 0.69444444 | E8: =E7*Assumptions!$B$18 -> 69.444444 | F8: average x peak multiplier
A9: Concurrent asks at peak | B9: =B8*Assumptions!$B$19 -> 0.027777778 | C9: =C8*Assumptions!$B$19 -> 0.27777778 | D9: =D8*Assumptions!$B$19 -> 2.7777778 | E9: =E8*Assumptions!$B$19 -> 277.77778 | F9: peak rate x time a worker is held (Little's law)
A10: App servers needed (t3.large) | B10: =MAX(IF(B4<=100,1,Assumptions!$B$23),ROUNDUP(B9/Assumptions!$B$20,0)) -> 1 | C10: =MAX(IF(C4<=100,1,Assumptions!$B$23),ROUNDUP(C9/Assumptions!$B$20,0)) -> 2 | D10: =MAX(IF(D4<=100,1,Assumptions!$B$23),ROUNDUP(D9/Assumptions!$B$20,0)) -> 2 | E10: =MAX(IF(E4<=100,1,Assumptions!$B$23),ROUNDUP(E9/Assumptions!$B$20,0)) -> 35 | F10: capacity or HA minimum
A11: Document files stored (GB) | B11: =B4*Assumptions!$B$16*Assumptions!$B$14/1024 -> 1.171875 | C11: =C4*Assumptions!$B$16*Assumptions!$B$14/1024 -> 11.71875 | D11: =D4*Assumptions!$B$16*Assumptions!$B$14/1024 -> 117.1875 | E11: =E4*Assumptions!$B$16*Assumptions!$B$14/1024 -> 11718.75 | F11: users x docs x file size
A12: Database data (GB) | B12: =B4*Assumptions!$B$16*Assumptions!$B$15/1024 -> 0.390625 | C12: =C4*Assumptions!$B$16*Assumptions!$B$15/1024 -> 3.90625 | D12: =D4*Assumptions!$B$16*Assumptions!$B$15/1024 -> 39.0625 | E12: =E4*Assumptions!$B$16*Assumptions!$B$15/1024 -> 3906.25 | F12: users x docs x DB MB per doc
A13: Database nodes (RDS) | B13: =IF(B4<=1000,1,MAX(1,ROUNDUP(B12/Assumptions!$B$22,0))) -> 1 | C13: =IF(C4<=1000,1,MAX(1,ROUNDUP(C12/Assumptions!$B$22,0))) -> 1 | D13: =IF(D4<=1000,1,MAX(1,ROUNDUP(D12/Assumptions!$B$22,0))) -> 1 | E13: =IF(E4<=1000,1,MAX(1,ROUNDUP(E12/Assumptions!$B$22,0))) -> 14 | F13: 1 small node up to 1,000 users; then sized by data per node
A14: LLM input tokens / month | B14: =B6*Assumptions!$B$10*Assumptions!$B$7 -> 1530000 | C14: =C6*Assumptions!$B$10*Assumptions!$B$7 -> 15300000 | D14: =D6*Assumptions!$B$10*Assumptions!$B$7 -> 153000000 | E14: =E6*Assumptions!$B$10*Assumptions!$B$7 -> 15300000000 | F14: asks reaching LLM x input tokens
A15: LLM output tokens / month | B15: =B6*Assumptions!$B$10*Assumptions!$B$8 -> 382500 | C15: =C6*Assumptions!$B$10*Assumptions!$B$8 -> 3825000 | D15: =D6*Assumptions!$B$10*Assumptions!$B$8 -> 38250000 | E15: =E6*Assumptions!$B$10*Assumptions!$B$8 -> 3825000000 | F15: asks reaching LLM x output tokens
A16: Embedding tokens / month | B16: =B6*Assumptions!$B$9+B5*Assumptions!$B$11*Assumptions!$B$12*Assumptions!$B$13 -> 477000 | C16: =C6*Assumptions!$B$9+C5*Assumptions!$B$11*Assumptions!$B$12*Assumptions!$B$13 -> 4770000 | D16: =D6*Assumptions!$B$9+D5*Assumptions!$B$11*Assumptions!$B$12*Assumptions!$B$13 -> 47700000 | E16: =E6*Assumptions!$B$9+E5*Assumptions!$B$11*Assumptions!$B$12*Assumptions!$B$13 -> 4770000000 | F16: questions + new documents (with overlap)
A17: Response data out (GB) | B17: =B6*Assumptions!$B$17/1024/1024 -> 0.01373291 | C17: =C6*Assumptions!$B$17/1024/1024 -> 0.1373291 | D17: =D6*Assumptions!$B$17/1024/1024 -> 1.373291 | E17: =E6*Assumptions!$B$17/1024/1024 -> 137.3291 | F17: asks x response size
A18: -- Paid AI APIs --
A19: Embeddings (text-embedding-3-small) | B19: =B16/1000000*Prices!$E$8 -> 0.00954 | C19: =C16/1000000*Prices!$E$8 -> 0.0954 | D19: =D16/1000000*Prices!$E$8 -> 0.954 | E19: =E16/1000000*Prices!$E$8 -> 95.4 | F19: tokens / 1M x price
A20: LLM cost if gpt-6-luna | B20: =B14/1000000*Prices!$E$4+B15/1000000*Prices!$E$5 -> 0.34425 | C20: =C14/1000000*Prices!$E$4+C15/1000000*Prices!$E$5 -> 3.4425 | D20: =D14/1000000*Prices!$E$4+D15/1000000*Prices!$E$5 -> 34.425 | E20: =E14/1000000*Prices!$E$4+E15/1000000*Prices!$E$5 -> 3442.5 | F20: input + output cost
A21: LLM cost if gpt-6.1-sol | B21: =B14/1000000*Prices!$E$6+B15/1000000*Prices!$E$7 -> 6.885 | C21: =C14/1000000*Prices!$E$6+C15/1000000*Prices!$E$7 -> 68.85 | D21: =D14/1000000*Prices!$E$6+D15/1000000*Prices!$E$7 -> 688.5 | E21: =E14/1000000*Prices!$E$6+E15/1000000*Prices!$E$7 -> 68850 | F21: input + output cost
A22: -- AWS infrastructure (us-east-1) --
A23: App servers (t3.large) | B23: =B10*Prices!$E$11*Assumptions!$B$4 -> 60.736 | C23: =C10*Prices!$E$11*Assumptions!$B$4 -> 121.472 | D23: =D10*Prices!$E$11*Assumptions!$B$4 -> 121.472 | E23: =E10*Prices!$E$11*Assumptions!$B$4 -> 2125.76 | F23: servers x hourly x hours
A24: Database instances | B24: =IF(B4<=1000,Prices!$E$13,B13*Prices!$E$14)*Assumptions!$B$4 -> 52.56 | C24: =IF(C4<=1000,Prices!$E$13,C13*Prices!$E$14)*Assumptions!$B$4 -> 52.56 | D24: =IF(D4<=1000,Prices!$E$13,D13*Prices!$E$14)*Assumptions!$B$4 -> 328.5 | E24: =IF(E4<=1000,Prices!$E$13,E13*Prices!$E$14)*Assumptions!$B$4 -> 4599 | F24: db.t3.medium up to 1,000 users; db.r6g.large Multi-AZ above
A25: Database storage (gp3) | B25: =B12*Prices!$E$15*IF(B4<=1000,1,2) -> 0.044921875 | C25: =C12*Prices!$E$15*IF(C4<=1000,1,2) -> 0.44921875 | D25: =D12*Prices!$E$15*IF(D4<=1000,1,2) -> 8.984375 | E25: =E12*Prices!$E$15*IF(E4<=1000,1,2) -> 898.4375 | F25: GB x price; doubled under Multi-AZ
A26: Database backups beyond free | B26: =MAX(0,B12*(Assumptions!$B$21-1))*Prices!$E$16 -> 0.018554688 | C26: =MAX(0,C12*(Assumptions!$B$21-1))*Prices!$E$16 -> 0.18554688 | D26: =MAX(0,D12*(Assumptions!$B$21-1))*Prices!$E$16 -> 1.8554688 | E26: =MAX(0,E12*(Assumptions!$B$21-1))*Prices!$E$16 -> 185.54688 | F26: only backup GB above DB size is billed
A27: S3 file storage | B27: =B11*Prices!$E$17 -> 0.026953125 | C27: =C11*Prices!$E$17 -> 0.26953125 | D27: =D11*Prices!$E$17 -> 2.6953125 | E27: =E11*Prices!$E$17 -> 269.53125 | F27: GB x price
A28: S3 requests | B28: =(B5*Assumptions!$B$11/1000*Prices!$E$18)+(B5*Assumptions!$B$11/1000*Prices!$E$19) -> 0.000324 | C28: =(C5*Assumptions!$B$11/1000*Prices!$E$18)+(C5*Assumptions!$B$11/1000*Prices!$E$19) -> 0.00324 | D28: =(D5*Assumptions!$B$11/1000*Prices!$E$18)+(D5*Assumptions!$B$11/1000*Prices!$E$19) -> 0.0324 | E28: =(E5*Assumptions!$B$11/1000*Prices!$E$18)+(E5*Assumptions!$B$11/1000*Prices!$E$19) -> 3.24 | F28: one PUT and one GET per new document
A29: Data transfer out | B29: =MAX(0,B17-Prices!$E$21)*Prices!$E$20 -> 0 | C29: =MAX(0,C17-Prices!$E$21)*Prices!$E$20 -> 0 | D29: =MAX(0,D17-Prices!$E$21)*Prices!$E$20 -> 0 | E29: =MAX(0,E17-Prices!$E$21)*Prices!$E$20 -> 3.3596191 | F29: GB above free allowance x price
A30: AWS infrastructure total (priced items only) | B30: =SUM(B23:B29) -> 113.38675 | C30: =SUM(C23:C29) -> 174.93954 | D30: =SUM(D23:D29) -> 463.53956 | E30: =SUM(E23:E29) -> 8084.8752 | F30: excludes UNPRICED items on Prices sheet
A31: -- Hostinger VPS (single server) --
A32: Hostinger plan used | B32: KVM 2 | C32: KVM 4 | D32: n/a | E32: n/a | F32: KVM 2 for 100 users, KVM 4 for 1,000; not suitable above that
A33: Hostinger total (priced items only) | B33: =Prices!$E$9 -> 14.99 | C33: =Prices!$E$10 -> 28.99 | D33: n/a | E33: n/a | F33: compute, storage, bandwidth are included in the plan
A34: -- Totals --
A35: AWS + gpt-6-luna + embeddings | B35: =B30+B20+B19 -> 113.74054 | C35: =C30+C20+C19 -> 178.47744 | D35: =D30+D20+D19 -> 498.91856 | E35: =E30+E20+E19 -> 11622.775
A36: AWS + gpt-6.1-sol + embeddings | B36: =B30+B21+B19 -> 120.28129 | C36: =C30+C21+C19 -> 243.88494 | D36: =D30+D21+D19 -> 1152.9936 | E36: =E30+E21+E19 -> 77030.275
A37: Hostinger + gpt-6-luna + embeddings | B37: =B33+B20+B19 -> 15.34379 | C37: =C33+C20+C19 -> 32.5279 | D37: n/a | E37: n/a | F37: n/a where one VPS is not enough
A38: Hostinger + gpt-6.1-sol + embeddings | B38: =B33+B21+B19 -> 21.88454 | C38: =C33+C21+C19 -> 97.9354 | D38: n/a | E38: n/a | F38: n/a where one VPS is not enough
A39: AWS + luna cost per registered user | B39: =B35/B4 -> 1.1374054 | C39: =C35/C4 -> 0.17847744 | D39: =D35/D4 -> 0.049891856 | E39: =E35/E4 -> 0.011622775
A40: -- Open-source model on a GPU (instead of the paid LLM) --
A41: One g5.xlarge GPU server, 24/7 | B41: =Prices!$E$12*Assumptions!$B$4 -> 734.38 | C41: =Prices!$E$12*Assumptions!$B$4 -> 734.38 | D41: =Prices!$E$12*Assumptions!$B$4 -> 734.38 | E41: =Prices!$E$12*Assumptions!$B$4 -> 734.38 | F41: hourly x hours; throughput NOT estimated, needs a benchmark
...
